<?xml version="1.0"?>
<robot xmlns:xacro="http://www.ros.org/wiki/xacro" name="robot_base">
    <link name="base_link">
        <visual>
            <geometry>
                <box size="0.5 0.4 0.15"/>
            </geometry>
            <origin xyz="0 0 0"/>
        </visual>

        <collision>
            <geometry>
                <box size="0.5 0.4 0.15"/>
            </geometry>
        </collision>

        <inertial>
            <mass value="5"/>
            <origin xyz="0 0 0"/>
            <inertia ixx="0.1" ixy="0" ixz="0" iyy="0.1" iyz="0" izz="0.1"/>
        </inertial>
    </link>

    <link name="left_wheel_link">
        <visual>
            <geometry>
                <cylinder radius="0.1" length="0.05"/>
            </geometry>
            <origin xyz="0 0 0" rpy="1.5708 0 0"/>
        </visual>
    </link>
    <joint name="left_wheel_joint" type="continuous">
        <parent link="base_link"/>
        <child link="left_wheel_link"/>
        <origin xyz="0 0.25 0" rpy="0 0 0"/>
        <axis xyz="0 1 0"/>
    </joint>



    <link name="right_wheel_link"> 
        <visual>
            <geometry>
                <cylinder radius="0.1" length="0.05"/>
            </geometry>
            <origin xyz="0 0 0" rpy="1.5708 0 0"/>
        </visual>
    </link>

    <joint name="right_wheel_joint" type="continuous">
        <parent link="base_link"/>
        <child link="right_wheel_link"/>
        <origin xyz="0 -0.25 0" rpy="0 0 0"/>
        <axis xyz="0 1 0"/>
    </joint>
</robot>
